<?xml version="1.0" ?>
<!--
  Digital-twin TurtleBot3 Burger.
  Based on turtlebot3_gazebo/models/turtlebot3_burger (Apache-2.0, ROBOTIS).
  Twin changes: topics moved under /sim/*, TF frames prefixed sim/, ground-truth
  OdometryPublisher, and a chemical dispersal motor (sprayer joint + particle
  emitter) for algae cleaning. Meshes come from turtlebot3_common (make sure
  turtlebot3_gazebo/models is on GZ_SIM_RESOURCE_PATH — the launch does this).
-->
<sdf version="1.8">
  <model name="burger_twin">
    <pose>0 0 0 0 0 0</pose>

    <link name="base_footprint"/>

    <link name="base_link">
      <inertial>
        <pose>-0.064 0 0.070 0 0 0</pose>
        <inertia>
          <ixx>1.9527e-02</ixx><ixy>0</ixy><ixz>0</ixz>
          <iyy>1.9527e-02</iyy><iyz>0</iyz><izz>1.9527e-02</izz>
        </inertia>
        <mass>8.2573504e-01</mass>
      </inertial>
      <collision name="base_collision">
        <pose>-0.032 0 0.070 0 0 0</pose>
        <geometry><box><size>0.14 0.14 0.14</size></box></geometry>
      </collision>
      <visual name="base_visual">
        <pose>-0.032 0 0 0 0 0</pose>
        <geometry>
          <mesh>
            <uri>model://turtlebot3_common/meshes/bases/burger_base.stl</uri>
            <scale>0.001 0.001 0.001</scale>
          </mesh>
        </geometry>
        <material>
          <ambient>0.15 0.45 0.6 1.0</ambient>
          <diffuse>0.15 0.45 0.6 1.0</diffuse>
        </material>
      </visual>
    </link>

    <link name="imu_link">
      <sensor name="tb3_imu" type="imu">
        <always_on>true</always_on>
        <update_rate>200</update_rate>
        <topic>/sim/imu</topic>
        <imu>
          <angular_velocity>
            <x><noise type="gaussian"><mean>0.0</mean><stddev>2e-4</stddev></noise></x>
            <y><noise type="gaussian"><mean>0.0</mean><stddev>2e-4</stddev></noise></y>
            <z><noise type="gaussian"><mean>0.0</mean><stddev>2e-4</stddev></noise></z>
          </angular_velocity>
          <linear_acceleration>
            <x><noise type="gaussian"><mean>0.0</mean><stddev>1.7e-2</stddev></noise></x>
            <y><noise type="gaussian"><mean>0.0</mean><stddev>1.7e-2</stddev></noise></y>
            <z><noise type="gaussian"><mean>0.0</mean><stddev>1.7e-2</stddev></noise></z>
          </linear_acceleration>
        </imu>
      </sensor>
    </link>

    <link name="base_scan">
      <inertial>
        <pose>-0.020 0 0.161 0 0 0</pose>
        <inertia>
          <ixx>0.0001</ixx><ixy>0</ixy><ixz>0</ixz>
          <iyy>0.0001</iyy><iyz>0</iyz><izz>0.0001</izz>
        </inertia>
        <mass>0.114</mass>
      </inertial>
      <collision name="lidar_sensor_collision">
        <pose>-0.020 0 0.161 0 0 0</pose>
        <geometry><cylinder><radius>0.0508</radius><length>0.055</length></cylinder></geometry>
      </collision>
      <visual name="lidar_sensor_visual">
        <pose>-0.032 0 0.171 0 0 0</pose>
        <geometry>
          <mesh>
            <uri>model://turtlebot3_common/meshes/sensors/lds.stl</uri>
            <scale>0.001 0.001 0.001</scale>
          </mesh>
        </geometry>
        <material>
          <ambient>0.2 0.2 0.2 1.0</ambient>
          <diffuse>0.2 0.2 0.2 1.0</diffuse>
        </material>
      </visual>
      <sensor name="hls_lfcd_lds" type="gpu_lidar">
        <always_on>true</always_on>
        <visualize>true</visualize>
        <pose>-0.032 0 0.171 0 0 0</pose>
        <update_rate>5</update_rate>
        <topic>/sim/scan</topic>
        <gz_frame_id>sim/base_scan</gz_frame_id>
        <lidar>
          <scan>
            <horizontal>
              <samples>360</samples>
              <resolution>1.0</resolution>
              <min_angle>0.0</min_angle>
              <max_angle>6.28</max_angle>
            </horizontal>
          </scan>
          <range>
            <!-- match the real LDS-02 (0.16-8.0 m) for twin fidelity -->
            <min>0.16</min>
            <max>8.0</max>
            <resolution>0.015</resolution>
          </range>
          <noise>
            <type>gaussian</type>
            <mean>0.0</mean>
            <stddev>0.01</stddev>
          </noise>
        </lidar>
      </sensor>
    </link>

    <link name="wheel_left_link">
      <inertial>
        <pose>0 0.08 0.023 -1.57 0 0</pose>
        <inertia>
          <ixx>5.445e-05</ixx><ixy>0</ixy><ixz>0</ixz>
          <iyy>5.445e-05</iyy><iyz>0</iyz><izz>1.089e-04</izz>
        </inertia>
        <mass>0.1</mass>
      </inertial>
      <collision name="wheel_left_collision">
        <pose>0 0.08 0.023 -1.57 0 0</pose>
        <geometry><cylinder><radius>0.033</radius><length>0.018</length></cylinder></geometry>
        <surface>
          <friction>
            <ode><mu>100000.0</mu><mu2>100000.0</mu2></ode>
          </friction>
          <contact>
            <ode><kp>1e+5</kp><kd>1</kd><max_vel>0.01</max_vel><min_depth>0.001</min_depth></ode>
          </contact>
        </surface>
      </collision>
      <visual name="wheel_left_visual">
        <pose>0 0.08 0.023 0 0 0</pose>
        <geometry>
          <mesh>
            <uri>model://turtlebot3_common/meshes/wheels/left_tire.stl</uri>
            <scale>0.001 0.001 0.001</scale>
          </mesh>
        </geometry>
        <material><ambient>0.2 0.2 0.2 1.0</ambient><diffuse>0.2 0.2 0.2 1.0</diffuse></material>
      </visual>
    </link>

    <link name="wheel_right_link">
      <inertial>
        <pose>0.0 -0.08 0.023 -1.57 0 0</pose>
        <inertia>
          <ixx>5.445e-05</ixx><ixy>0</ixy><ixz>0</ixz>
          <iyy>5.445e-05</iyy><iyz>0</iyz><izz>1.089e-04</izz>
        </inertia>
        <mass>0.1</mass>
      </inertial>
      <collision name="wheel_right_collision">
        <pose>0.0 -0.08 0.023 -1.57 0 0</pose>
        <geometry><cylinder><radius>0.033</radius><length>0.018</length></cylinder></geometry>
        <surface>
          <friction>
            <ode><mu>100000.0</mu><mu2>100000.0</mu2></ode>
          </friction>
          <contact>
            <ode><kp>1e+5</kp><kd>1</kd><max_vel>0.01</max_vel><min_depth>0.001</min_depth></ode>
          </contact>
        </surface>
      </collision>
      <visual name="wheel_right_visual">
        <pose>0.0 -0.08 0.023 0 0 0</pose>
        <geometry>
          <mesh>
            <uri>model://turtlebot3_common/meshes/wheels/right_tire.stl</uri>
            <scale>0.001 0.001 0.001</scale>
          </mesh>
        </geometry>
        <material><ambient>0.2 0.2 0.2 1.0</ambient><diffuse>0.2 0.2 0.2 1.0</diffuse></material>
      </visual>
    </link>

    <link name="caster_back_link">
      <pose>-0.081 0 -0.004 -1.57 0 0</pose>
      <inertial>
        <mass>0.005</mass>
        <inertia>
          <ixx>0.00001</ixx><ixy>0</ixy><ixz>0</ixz>
          <iyy>0.00001</iyy><iyz>0</iyz><izz>0.00001</izz>
        </inertia>
      </inertial>
      <collision name="collision">
        <geometry><sphere><radius>0.005</radius></sphere></geometry>
        <surface>
          <contact>
            <ode><kp>1e+5</kp><kd>1</kd><max_vel>0.01</max_vel><min_depth>0.001</min_depth></ode>
          </contact>
        </surface>
      </collision>
    </link>

    <!-- chemical dispersal motor: visible spinner + particle mist -->
    <link name="sprayer_link">
      <pose>0.045 0 0.135 0 0 0</pose>
      <inertial>
        <mass>0.02</mass>
        <inertia>
          <ixx>1e-05</ixx><ixy>0</ixy><ixz>0</ixz>
          <iyy>1e-05</iyy><iyz>0</iyz><izz>1e-05</izz>
        </inertia>
      </inertial>
      <visual name="nozzle">
        <geometry><cylinder><radius>0.018</radius><length>0.04</length></cylinder></geometry>
        <material>
          <ambient>0.1 0.7 0.3 1</ambient>
          <diffuse>0.1 0.8 0.3 1</diffuse>
          <emissive>0.02 0.2 0.05 1</emissive>
        </material>
      </visual>
      <visual name="fin">
        <pose>0.025 0 0.012 0 0 0</pose>
        <geometry><box><size>0.025 0.006 0.01</size></box></geometry>
        <material><ambient>0.9 0.9 0.9 1</ambient><diffuse>0.9 0.9 0.9 1</diffuse></material>
      </visual>
      <particle_emitter name="chem" type="point">
        <!-- pitched -90 deg so particles rise; scatter_ratio 0 keeps the
             chemical mist invisible to the twin's lidar -->
        <pose>0 0 0.03 0 -1.5708 0</pose>
        <emitting>false</emitting>
        <particle_size>0.02 0.02 0.02</particle_size>
        <lifetime>1.4</lifetime>
        <rate>150</rate>
        <min_velocity>0.2</min_velocity>
        <max_velocity>0.45</max_velocity>
        <scale_rate>1.5</scale_rate>
        <color_start>0.5 1.0 0.6 0.9</color_start>
        <color_end>0.2 0.7 0.4 0.0</color_end>
        <particle_scatter_ratio>0.0</particle_scatter_ratio>
        <topic>/sim/sprayer_particles</topic>
      </particle_emitter>
    </link>

    <joint name="base_joint" type="fixed">
      <parent>base_footprint</parent>
      <child>base_link</child>
      <pose>0.0 0.0 0.010 0 0 0</pose>
    </joint>

    <joint name="wheel_left_joint" type="revolute">
      <parent>base_link</parent>
      <child>wheel_left_link</child>
      <pose>0.0 0.08 0.023 -1.57 0 0</pose>
      <axis>
        <xyz>0 0 1</xyz>
        <limit><effort>20</effort></limit>
      </axis>
    </joint>

    <joint name="wheel_right_joint" type="revolute">
      <parent>base_link</parent>
      <child>wheel_right_link</child>
      <pose>0.0 -0.08 0.023 -1.57 0 0</pose>
      <axis>
        <xyz>0 0 1</xyz>
        <limit><effort>20</effort></limit>
      </axis>
    </joint>

    <joint name="caster_back_joint" type="ball">
      <parent>base_link</parent>
      <child>caster_back_link</child>
    </joint>

    <joint name="imu_joint" type="fixed">
      <parent>base_link</parent>
      <child>imu_link</child>
      <pose>-0.032 0 0.068 0 0 0</pose>
    </joint>

    <joint name="lidar_joint" type="fixed">
      <parent>base_link</parent>
      <child>base_scan</child>
      <pose>-0.032 0 0.171 0 0 0</pose>
    </joint>

    <joint name="sprayer_joint" type="revolute">
      <parent>base_link</parent>
      <child>sprayer_link</child>
      <axis>
        <xyz>0 0 1</xyz>
        <limit><effort>2</effort></limit>
        <dynamics><damping>0.001</damping></dynamics>
      </axis>
    </joint>

    <plugin filename="gz-sim-diff-drive-system" name="gz::sim::systems::DiffDrive">
      <left_joint>wheel_left_joint</left_joint>
      <right_joint>wheel_right_joint</right_joint>
      <wheel_separation>0.160</wheel_separation>
      <wheel_radius>0.033</wheel_radius>
      <max_linear_acceleration>1.0</max_linear_acceleration>
      <topic>/sim/cmd_vel</topic>
      <odom_topic>/sim/odom</odom_topic>
      <frame_id>sim/odom</frame_id>
      <child_frame_id>sim/base_footprint</child_frame_id>
      <odom_publish_frequency>30</odom_publish_frequency>
      <tf_topic>/sim/tf</tf_topic>
    </plugin>

    <plugin filename="gz-sim-joint-state-publisher-system" name="gz::sim::systems::JointStatePublisher">
      <topic>/sim/joint_states</topic>
      <joint_name>wheel_left_joint</joint_name>
      <joint_name>wheel_right_joint</joint_name>
    </plugin>

    <!-- exact world pose of the twin (a digital twin knows where it is) -->
    <plugin filename="gz-sim-odometry-publisher-system" name="gz::sim::systems::OdometryPublisher">
      <odom_topic>/sim/ground_truth</odom_topic>
      <odom_frame>map</odom_frame>
      <robot_base_frame>sim/base_footprint</robot_base_frame>
      <odom_publish_frequency>20</odom_publish_frequency>
      <tf_topic>/sim/ground_truth_tf_unused</tf_topic>
      <dimensions>2</dimensions>
    </plugin>

    <plugin filename="gz-sim-joint-controller-system" name="gz::sim::systems::JointController">
      <joint_name>sprayer_joint</joint_name>
      <topic>/sim/sprayer_cmd</topic>
      <initial_velocity>0.0</initial_velocity>
    </plugin>
  </model>
</sdf>
